Workbook

Sheet SOA
A1: Zetas Zemin | H1: =TODAY() -> 46261
A2: =_xlfn.CONCAT("Statement of Account as of ",TEXT(H1,"MMMMMMM DD, YYYY")) -> Statement of Account as of August 27, 2026
A4: Invoice No | B4: Invoice Date | C4: Invoice Amount | D4: Payment Date | E4: Payment Amount | F4: Balance | G4: Description | H4: Remarks
A5: ZETDU-01151 | B5: 45715 | C5: =421000*1.05 -> 442050 | D5: 45715 | E5: =Table13212[[#This Row],[Invoice Amount]] -> 442050 | F5: =Table13212[[#This Row],[Invoice Amount]]-Table13212[[#This Row],[Payment Amount]] -> 0 | G5: Enabling works design & early preparation works - PC01 - Stage 1A | J5: 442050
A6: ZETDU-01171 | B6: 45746 | C6: =842000*1.05 -> 884100 | D6: 45827 | E6: 842000 | F6: =Table13212[[#This Row],[Invoice Amount]]-Table13212[[#This Row],[Payment Amount]] -> 42100 | G6: Enabling works design & early preparation works - PC02 - Stage 1A | J6: 842000
A7: ZETDU-01176 | B7: 45776 | C7: =1263000*1.05 -> 1326150 | D7: 45834 | E7: 1263000 | F7: =Table13212[[#This Row],[Invoice Amount]]-Table13212[[#This Row],[Payment Amount]] -> 63150 | G7: Enabling works design & early preparation works - PC03 - Stage 1A | J7: 1263000
A8: ZETDU-01189 | B8: 45838 | C8: =1684000*1.05 -> 1768200 | D8: 45839 | E8: 1684000 | F8: =Table13212[[#This Row],[Invoice Amount]]-Table13212[[#This Row],[Payment Amount]] -> 84200 | G8: Enabling works design & early preparation works - PC04 - Stage 1A | J8: 1684000
A9: ZETDU-01202 | B9: 45853 | C9: 17877955 | D9: 45857 | E9: 17026624 | F9: =Table13212[[#This Row],[Invoice Amount]]-Table13212[[#This Row],[Payment Amount]] -> 851331.18 | G9: Enabling works design & early preparation works - PC05 - 10% of the contract - Stage 1B | J9: 17026624
A10: ZETDU-01203 | B10: 45855 | C10: 645750 | D10: 45861 | E10: 615000 | F10: =Table13212[[#This Row],[Invoice Amount]]-Table13212[[#This Row],[Payment Amount]] -> 30750 | G10: Enabling works design & early preparation works - PC06 - Variation 01 | J10: 615000
A11: ZETDU-01221 | B11: 45894 | C11: 4522468.5 | D11: 45897 | E11: =Table13212[[#This Row],[Invoice Amount]]*100/105 -> 4307112.8 | F11: =Table13212[[#This Row],[Invoice Amount]]-Table13212[[#This Row],[Payment Amount]] -> 215355.64 | G11: Enabling works design & early preparation works - PC06 - Stage 1B | J11: 4307112.8
A12: ZETDU-01243 | B12: 45947 | C12: 6416893.9 | D12: 45987 | E12: 6111326.6 | F12: =Table13212[[#This Row],[Invoice Amount]]-Table13212[[#This Row],[Payment Amount]] -> 305567.33 | G12: Enabling works design & early preparation works - PC07 - Stage 1B | J12: 6111326.6
A13: ZETDU-01249 | B13: 45964 | C13: 10452758 | D13: 45987 | E13: 9955007.8 | F13: =Table13212[[#This Row],[Invoice Amount]]-Table13212[[#This Row],[Payment Amount]] -> 497750.39 | G13: Enabling works design & early preparation works - PC08 - Stage 1B | J13: 9955007.8
A14: ZETDU-01263 | B14: 45981 | C14: 8372268.5 | D14: 46010 | E14: =7973589.05 -> 7973589 | F14: =Table13212[[#This Row],[Invoice Amount]]-Table13212[[#This Row],[Payment Amount]] -> 398679.45 | G14: Enabling works design & early preparation works - PC09 - Stage 1B | J14: 7973589
A15: ZETDU-01288 | B15: 46008 | C15: 2924079.9 | D15: 46037 | E15: 2784838 | F15: =Table13212[[#This Row],[Invoice Amount]]-Table13212[[#This Row],[Payment Amount]] -> 139241.9 | G15: Enabling works design & early preparation works - PC10 - Stage 1B | J15: 2784838
A16: ZETDU-01294 | B16: 46037 | C16: 2210672.6 | D16: 46057 | E16: 2105402.4 | F16: =Table13212[[#This Row],[Invoice Amount]]-Table13212[[#This Row],[Payment Amount]] -> 105270.15 | G16: Enabling works design & early preparation works - PC11 - Stage 1B | J16: 2105402.4
A17: ZETDU-01308 | B17: 46069 | C17: 6304870.8 | D17: 46091 | E17: 6004638.8 | F17: =Table13212[[#This Row],[Invoice Amount]]-Table13212[[#This Row],[Payment Amount]] -> 300231.94 | G17: Enabling works design & early preparation works - PC12 - Stage 1B | J17: 6004638.8
A18: ZETDU-01325 | B18: 46107 | C18: 10367006 | D18: 46122 | E18: 9873339.4 | F18: =Table13212[[#This Row],[Invoice Amount]]-Table13212[[#This Row],[Payment Amount]] -> 493666.97 | G18: Enabling works design & early preparation works - PC13 - Stage 1B | J18: 9873339.4
A19: ZETDU-01332 | B19: 46139 | C19: 4210319.3 | D19: 46146 | E19: 4009827.9 | F19: =Table13212[[#This Row],[Invoice Amount]]-Table13212[[#This Row],[Payment Amount]] -> 200491.39 | G19: Enabling works design & early preparation works - PC14 - Stage 1B | J19: 4009827.9
A20: ZETDU-01363 | B20: 46175 | C20: 8441929.2 | D20: 46191 | E20: 8039932.5 | F20: =Table13212[[#This Row],[Invoice Amount]]-Table13212[[#This Row],[Payment Amount]] -> 401996.63 | G20: Enabling works design & early preparation works - PC15 - Stage 1B | J20: 8039932.5
A21: ZETDU-01365 | B21: 46197 | C21: 15987204 | D21: 46230 | E21: =3996801.01 -> 3996801 | F21: =Table13212[[#This Row],[Invoice Amount]]-Table13212[[#This Row],[Payment Amount]] -> 11990403 | G21: Enabling works design & early preparation works - PC16 - Stage 1B | J21: 3996801
D22: 46234 | E22: 11419431 | F22: =F21+Table13212[[#This Row],[Invoice Amount]]-Table13212[[#This Row],[Payment Amount]] -> 570971.57 | J22: 11419431
A23: ZETDU-01371 | B23: 46227 | C23: 12236446 | D23: 46247 | E23: 11653758 | F23: =Table13212[[#This Row],[Invoice Amount]]-Table13212[[#This Row],[Payment Amount]] -> 582687.9 | G23: Enabling works design & early preparation works - PC17 - Stage 1B | J23: =Table13212[[#This Row],[Invoice Amount]]*100/105 -> 11653758
A24: ZETDU-01382 | B24: 46254 | C24: 10801173 | F24: =Table13212[[#This Row],[Invoice Amount]]-Table13212[[#This Row],[Payment Amount]] -> 10801173 | G24: Enabling works design & early preparation works - PC18 - Stage 1B | L24: =Table13212[[#This Row],[Balance]]*100/105 -> 10286831 | M24: =L24*25% -> 2571707.9
A25: Total - AED | C25: =SUBTOTAL(109,C5:C24) -> 1.2619229e+08 | E25: =SUBTOTAL(109,E5:E24) -> 1.1010768e+08 | F25: =Table13212[[#This Row],[Invoice Amount]]-Table13212[[#This Row],[Payment Amount]] -> 16084615 | H25: -
A26: % of Amount paid | C26: =E25/C25 -> 0.87253885
F27: =SUM(F5:F20) -> 4129783 | G27: Outstanding VAT Amount
F28: =F27-C5 -> 3687733 | G28: Outstanding VAT Amount Less First Invoice
A29: Payment Summary | N29: 1280682.8
A30: Date | B30: Amount | N30: 1282261
A31: 45715 | B31: 442050 | F31: =C23*5/105 -> 582687.9
A32: 45827 | B32: 842000 | F32: =SUM(F22,F5:F20) -> 4700754.5 | N32: =N29-N30 -> -1578.23
A33: 45834 | B33: 1263000 | F33: =F32+F31 -> 5283442.4 | J33: 98453921 | O33: 3.6456
A34: 45839 | B34: 1684000
A35: 45857 | B35: 17026624 | E35: =C23*100/105 -> 11653758
A36: 45861 | B36: 615000 | E36: =E35*25% -> 2913439.5
A37: 45897 | B37: 4307112.8
A38: 45987 | B38: =E12 -> 6111326.6
A39: 45987 | B39: 9955007.8
A40: 46010 | B40: 7973589
A41: 46037 | B41: 2784838
...

Sheet Summary
A1: Zetas Zemin Teknologisi | H1: =TODAY() -> 46261
A2: =_xlfn.CONCAT("Statement of Account as of ",TEXT(H1,"MMMMMMM DD, YYYY")) -> Statement of Account as of August 27, 2026
A5: Scope | B5: Contract value Inclu VAT | C5: Amount Invoiced | D5: Payment | E5: Total Balance | F5: Due Balance | G5: Not Due | H5: Paid % to Contract
A6: Main Contract | B6: =B14*1.05 -> 1.7877955e+08 | C6: ='Main Contract'!E32 -> 1.2554654e+08 | D6: ='Main Contract'!F32 -> 1.0949268e+08 | E6: =Table210[[#This Row],[Contract value Inclu VAT]]-Table210[[#This Row],[Payment]] -> 69286867 | F6: =Table210[[#This Row],[Amount Invoiced]]-Table210[[#This Row],[Payment]] -> 16053865 | G6: =Table210[[#This Row],[Contract value Inclu VAT]]-Table210[[#This Row],[Amount Invoiced]] -> 53233002 | H6: =Table210[[#This Row],[Payment]]/Table210[[#This Row],[Contract value Inclu VAT]] -> 0.61244523
A7: Variation | B7: =Variations!D75 -> 645750 | C7: =Variations!E75 -> 645750 | D7: =Variations!G75 -> 615000 | E7: =Table210[[#This Row],[Contract value Inclu VAT]]-Table210[[#This Row],[Payment]] -> 30750 | F7: =Table210[[#This Row],[Amount Invoiced]]-Table210[[#This Row],[Payment]] -> 30750 | G7: =Table210[[#This Row],[Contract value Inclu VAT]]-Table210[[#This Row],[Amount Invoiced]] -> 0 | H7: =Table210[[#This Row],[Payment]]/Table210[[#This Row],[Contract value Inclu VAT]] -> 0.95238095
A8: Total | B8: =SUBTOTAL(109,B6:B7) -> 1.794253e+08 | C8: =SUBTOTAL(109,C6:C7) -> 1.2619229e+08 | D8: =SUBTOTAL(109,D6:D7) -> 1.1010768e+08 | E8: =Table210[[#This Row],[Contract value Inclu VAT]]-Table210[[#This Row],[Payment]] -> 69317617 | F8: =SUBTOTAL(109,F6:F7) -> 16084615 | G8: =Table210[[#This Row],[Contract value Inclu VAT]]-Table210[[#This Row],[Amount Invoiced]] -> 53233002
A10: Summary_Main Contract | F10: =B8-D8 -> 69317617 | H10: =B8+72000000 -> 2.514253e+08 | K10: Contract+Variation | L10: =B8 -> 1.794253e+08
A11: Phase | B11: Contract Value Exclu. VAT | C11: Payment Excluding VAT | D11: Balance | F11: =F10+72000000 -> 1.4131762e+08 | H11: 115000000 | K11: Addition | L11: 71000000
A12: Stage 1A | B12: =4210000 -> 4210000 | C12: =Table311[[#This Row],[Contract Value Exclu. VAT]] -> 4210000 | D12: =B12-C12 -> 0 | H12: 53000000 | K12: Total | L12: =SUM(L10:L11) -> 2.504253e+08
A13: Stage 1B | B13: =166056235 -> 166056235 | C13: =SUM('Main Contract'!F11:F30) -> 1.0526163e+08 | D13: =B13-C13 -> 60794605 | H13: =D8 -> 1.1010768e+08 | K13: Paid | L13: =-D8 -> -1.1010768e+08
A14: Total | B14: =SUBTOTAL(109,B12:B13) -> 170266235 | C14: =SUBTOTAL(109,C12:C13) -> 1.0947163e+08 | D14: =SUBTOTAL(109,D12:D13) -> 60794605 | H14: =H10-H11-H12-H13 -> -26682383 | K14: Receivables in 2026 | L14: =-(105569316+7932157) -> -113501473
K15: Escrow balance | L15: -53137785
K16: Shortfall | L16: =SUM(L12:L15) -> -26321641

Sheet Main Contract
A1: =Summary!A1 -> Zetas Zemin Teknologisi | H1: =TODAY() -> 46261
A2: =_xlfn.CONCAT("Statement of Account as of ",TEXT(H1,"MMMMMMM DD, YYYY")) -> Statement of Account as of August 27, 2026
A5: Particulars | B5: Contract Value --AED-- | C5: Vat 5% --AED-- | D5: Total Value --AED-- | E5: Amount Invoiced AED | F5: Payment AED | G5: Balance --AED-- | I5: Amount AED | J5: Narration | K5: Date
A6: Contract Value | B6: =Summary!B14 -> 170266235 | C6: =B6*5% -> 8513311.8 | D6: =B6+C6 -> 1.7877955e+08
A7: Stag 1A - Enabling works design & early prepation works - PC01 | E7: =421000*1.05 -> 442050 | F7: =Table17[[#This Row],[Amount Invoiced AED]] -> 442050 | G7: =E7-F7 -> 0 | I7: =Table17[[#This Row],[Payment AED]] -> 442050 | J7: Funds transferred from ADCB LLC | K7: 27.02.2025 | M7: =Table17[[#This Row],[Amount Invoiced AED]]*100/105 -> 421000
A8: Stag 1A - Enabling works design & early prepation works - PC02 | E8: 884100 | F8: 842000 | G8: =E8-F8 -> 42100 | I8: =Table17[[#This Row],[Payment AED]] -> 842000 | J8: Funds transferred from CBD Escrow | K8: 19.06.2025 | M8: =Table17[[#This Row],[Amount Invoiced AED]]*100/105 -> 842000
A9: Stag 1A - Enabling works design & early prepation works - PC03 | E9: 1326150 | F9: 1263000 | G9: =E9-F9 -> 63150 | I9: =Table17[[#This Row],[Payment AED]] -> 1263000 | J9: Funds transferred from CBD Escrow | K9: 26.06.2025 | M9: =Table17[[#This Row],[Amount Invoiced AED]]*100/105 -> 1263000
A10: Stag 1A - Enabling works design & early prepation works - PC04 | E10: 1768200 | F10: 1684000 | G10: =E10-F10 -> 84200 | I10: =Table17[[#This Row],[Payment AED]] -> 1684000 | J10: Funds transferred from CBD Escrow | K10: 01.07.2025 | M10: =Table17[[#This Row],[Amount Invoiced AED]]*100/105 -> 1684000
A11: Stag 1B - Enabling works design & early prepation works - PC05 - 10% | E11: 17877955 | F11: 17026624 | G11: =E11-F11 -> 851331.18 | I11: =Table17[[#This Row],[Payment AED]] -> 17026624 | J11: Funds transferred from CBD Escrow | K11: 19.07.2025
G12: =E12-F12 -> 0 | I12: =Table17[[#This Row],[Payment AED]] -> 0 | M12: =Table17[[#This Row],[Amount Invoiced AED]]/$D$6 -> 0
G13: =E13-F13 -> 0 | I13: =Table17[[#This Row],[Payment AED]] -> 0 | M13: =Table17[[#This Row],[Amount Invoiced AED]]/$D$6 -> 0
G14: =E14-F14 -> 0 | I14: =Table17[[#This Row],[Payment AED]] -> 0 | M14: =Table17[[#This Row],[Amount Invoiced AED]]/$D$6 -> 0
G15: =E15-F15 -> 0 | I15: =Table17[[#This Row],[Payment AED]] -> 0 | M15: =Table17[[#This Row],[Amount Invoiced AED]]/$D$6 -> 0
G16: =E16-F16 -> 0 | I16: =Table17[[#This Row],[Payment AED]] -> 0 | M16: =Table17[[#This Row],[Amount Invoiced AED]]/$D$6 -> 0
G17: =E17-F17 -> 0 | I17: =Table17[[#This Row],[Payment AED]] -> 0 | M17: =Table17[[#This Row],[Amount Invoiced AED]]/$D$6 -> 0
G18: =E18-F18 -> 0 | I18: =Table17[[#This Row],[Payment AED]] -> 0 | M18: =Table17[[#This Row],[Amount Invoiced AED]]/$D$6 -> 0
A19: Stag 1B - Enabling works design & early prepation works - PC06 | E19: 4522468.5 | F19: 4307112.8 | G19: =E19-F19 -> 215355.64 | I19: =Table17[[#This Row],[Payment AED]] -> 4307112.8 | J19: Funds transferred from CBD Escrow | K19: 28.08.2025
A20: Stag 1B - Enabling works design & early prepation works - PC07 | E20: 6416893.9 | F20: 6111327 | G20: =E20-F20 -> 305566.93 | I20: =Table17[[#This Row],[Payment AED]] -> 6111327 | J20: Funds transferred from CBD Escrow | K20: 26.11.2025
A21: Stag 1B - Enabling works design & early prepation works - PC08 | E21: 10452758 | F21: 9955008 | G21: =E21-F21 -> 497750.19 | I21: =Table17[[#This Row],[Payment AED]] -> 9955008 | J21: Funds transferred from CBD Escrow | K21: 26.08.2025
A22: Stag 1B - Enabling works design & early prepation works - PC09 | E22: 8372268.5 | F22: 7973589 | G22: =E22-F22 -> 398679.45 | I22: =Table17[[#This Row],[Payment AED]] -> 7973589 | J22: Funds transferred from CBD Escrow | K22: 19.12.2025
A23: Stag 1B - Enabling works design & early prepation works - PC10 | E23: 2924079.9 | F23: 2784838 | G23: =E23-F23 -> 139241.9 | I23: =Table17[[#This Row],[Payment AED]] -> 2784838 | J23: Funds transferred from CBD Escrow | K23: 15.01.2026
A24: Stag 1B - Enabling works design & early prepation works - PC11 | E24: 2210672.5 | F24: 2105402.4 | G24: =E24-F24 -> 105270.12 | I24: =Table17[[#This Row],[Payment AED]] -> 2105402.4 | J24: Funds transferred from CBD Escrow | K24: 04.02.2026
A25: Stag 1B - Enabling works design & early prepation works - PC12 | E25: 6304870.8 | F25: 6004638.8 | G25: =E25-F25 -> 300231.94 | I25: =Table17[[#This Row],[Payment AED]] -> 6004638.8 | J25: Funds transferred from CBD Escrow | K25: 10.03.2026
A26: Stag 1B - Enabling works design & early prepation works - PC13 | E26: 10367006 | F26: 9873339.4 | G26: =E26-F26 -> 493666.97 | I26: =Table17[[#This Row],[Payment AED]] -> 9873339.4 | J26: Funds transferred from CBD Escrow | K26: 04.02.2026
A27: Stag 1B - Enabling works design & early prepation works - PC14 | E27: 4210319.3 | F27: 4009827.9 | G27: =E27-F27 -> 200491.39 | I27: =Table17[[#This Row],[Payment AED]] -> 4009827.9 | J27: Funds transferred from CBD Escrow | K27: 04.05.2026
A28: Stag 1B - Enabling works design & early prepation works - PC15 | E28: 8441929.2 | F28: 8039932.5 | G28: =E28-F28 -> 401996.63 | I28: =Table17[[#This Row],[Payment AED]] -> 8039932.5 | J28: Funds transferred from CBD Escrow | K28: 18.06.2026
A29: Stag 1B - Enabling works design & early prepation works - PC16 | E29: 15987204 | F29: =3996801.01+11419431.44 -> 15416232 | G29: =E29-F29 -> 570971.57 | I29: =Table17[[#This Row],[Payment AED]] -> 15416232 | J29: Funds transferred from ADCB LLC & CBD Escrow | K29: 27.07.2026 + 31.07.2026
A30: Stag 1B - Enabling works design & early prepation works - PC17 | E30: 12236446 | F30: 11653758 | G30: =E30-F30 -> 582687.9 | I30: =Table17[[#This Row],[Payment AED]] -> 11653758 | J30: Funds transferred from CBD Escrow | K30: 13.08.2026
A31: Stag 1B - Enabling works design & early prepation works - PC18 | E31: 10801173 | G31: =E31-F31 -> 10801173 | I31: =Table17[[#This Row],[Payment AED]] -> 0
A32: Total | B32: =SUBTOTAL(109,B6:B27) -> 170266235 | C32: =SUBTOTAL(109,C6:C27) -> 8513311.8 | D32: =SUBTOTAL(109,D6:D27) -> 1.7877955e+08 | E32: =SUBTOTAL(109,E6:E31) -> 1.2554654e+08 | F32: =SUM(F6:F31) -> 1.0949268e+08 | G32: =SUBTOTAL(109,G6:G31) -> 16053865 | I32: =SUM(I7:I30) -> 1.0949268e+08

Sheet Variations
A1: Arup Gulf Limited | I1: =[1]Summary!I1 -> 46231
A2: =_xlfn.CONCAT("Statement of Account as of ",TEXT(I1,"MMMMMMM DD, YYYY")) -> Statement of Account as of July 28, 2026
A4: =Summary!A7 -> Variation
A5: Particulars | B5: Contract Value --AED-- | C5: Vat 5% --AED-- | D5: Total Value --AED-- | E5: Amount Invoiced | F5: Invoiced % to Contract | G5: Payment | H5: Balance --AED-- | J5: Amount AED | K5: Payment Transferred From | L5: Date
A6: Variation 1: Sales Gallery - Shifting | B6: 615000 | C6: =Table158[[#This Row],[Contract Value --AED--]]*0.05 -> 30750 | D6: =SUM(Table158[[#This Row],[Contract Value --AED--]:[Vat 5% --AED--]]) -> 645750
A7: Enabling works design & early prepation works - PC06 - Variation 01 | E7: =D6 -> 645750 | F7: =Table158[[#This Row],[Amount Invoiced]]/$D$6 -> 1 | G7: 615000 | H7: =Table158[[#This Row],[Amount Invoiced]]-Table158[[#This Row],[Payment]] -> 30750 | J7: =Table158[[#This Row],[Payment]] -> 615000 | K7: Funds transferred from CBD Escrow | L7: 23.07.2025
T8: 25000
T9: =T8*0.6 -> 15000
T10: =T8*0.3 -> 7500
T11: =T8*0.1 -> 2500
A75: Total Variation + Others | B75: =SUBTOTAL(109,B6:B74) -> 615000 | C75: =SUBTOTAL(109,C6:C74) -> 30750 | D75: =SUM(Table158[[#This Row],[Contract Value --AED--]:[Vat 5% --AED--]]) -> 645750 | E75: =E7 -> 645750 | F75: =Table158[[#This Row],[Amount Invoiced]]/Table158[[#This Row],[Total Value --AED--]] -> 1 | G75: =G7 -> 615000 | H75: =Table158[[#This Row],[Amount Invoiced]]-Table158[[#This Row],[Payment]] -> 30750

Sheet Sheet1
A1: Zetas
A3: Particular | B3: Amount
A4: Contract+Variation | B4: 1.794253e+08
A5: Addition | B5: 71000000
A6: Total | B6: 2.504253e+08
A7: Paid | B7: -61114590
A8: Receivables in 2026 | B8: -113501473
A9: Escrow balance | B9: -53137785
A10: Shortfall | B10: 22671449

Sheet 14.Nov.2024
A1: Arup Gulf Limited | H1: 45610
A2: =_xlfn.CONCAT("Statement of Account as of ",TEXT(H1,"MMMMMMM DD, YYYY")) -> Statement of Account as of November 14, 2024
A4: Particulars | B4: Contract Value --AED-- | C4: Payment --AED-- | D4: Balance --AED-- | E4: Remarks | F4: Notes
A5: Contract Value - 20% of AED 2,546,250 | B5: 509250 | D5: =B5-C5 -> 509250 | E5: - | F5: -
A6: Transfer on 10-Jul-2023 against 20% Of Contract Value | C6: 509250 | D6: =D5+'14.Nov.2024'!$B6-'14.Nov.2024'!$C6 -> 0 | E6: - | F6: -
A7: Contract Value - 20% of AED 2,546,250 | B7: 509250 | D7: =D6+'14.Nov.2024'!$B7-'14.Nov.2024'!$C7 -> 509250 | E7: - | F7: - | H7: 509250 | I7: Mobilisation
A8: Transfer on 10-Jul-2023 against 20% Of Contract Value | C8: 509250 | D8: =D7+'14.Nov.2024'!$B8-'14.Nov.2024'!$C8 -> 0 | E8: - | F8: - | H8: 135800.7 | I8: End Jul, 2023 | J8: Concept | K8: Scheme | L8: Digital Design | M8: Total
A9: Invoice No. 57-230079 - Dated 17-Aug-2023 | B9: 135800.7 | D9: =D8+'14.Nov.2024'!$B9-'14.Nov.2024'!$C9 -> 135800.7 | E9: - | F9: - | H9: 135799.65 | I9: End Aug, 2023 | J9: =485000 -> 485000 | K9: 970000 | L9: 970000 | M9: =SUM(J9:L9) -> 2425000
A10: Transfer on 28-Aug-2023 against Invoice No. 57-230079 | C10: 135800.7 | D10: =D9+'14.Nov.2024'!$B10-'14.Nov.2024'!$C10 -> 0 | E10: - | F10: - | H10: 135799.65 | I10: End Sep, 2023 | J10: =J9*5% -> 24250 | K10: =K9*5% -> 48500 | L10: =L9*5% -> 48500 | M10: =M9*5% -> 121250
A11: Invoice No. 57-230090 - Dated 31-Aug-2023 | B11: 135799.65 | D11: =D10+'14.Nov.2024'!$B11-'14.Nov.2024'!$C11 -> 135799.65 | E11: - | F11: - | H11: 203700 | I11: End Oct, 2023 | J11: =J9+J10 -> 509250 | K11: =K9+K10 -> 1018500 | L11: =L9+L10 -> 1018500 | M11: =M9+M10 -> 2546250
A12: Transfer on 27-Sep-2023 against Invoice No. 57-230090 | C12: 135799.65 | D12: =D11+'14.Nov.2024'!$B12-'14.Nov.2024'!$C12 -> 0 | E12: - | F12: - | H12: 203700 | I12: End Nov, 2023
A13: Invoice No. 57-230106 - Dated 30-Sep-2023 | B13: 135799.65 | D13: =D12+'14.Nov.2024'!$B13-'14.Nov.2024'!$C13 -> 135799.65 | E13: - | F13: - | H13: 203700 | I13: End Dec, 2023
A14: Transfer on 27-Nov-2023 against Invoice No. 57-230106 | C14: 135799.65 | D14: =D13+'14.Nov.2024'!$B14-'14.Nov.2024'!$C14 -> 0 | E14: - | F14: - | H14: 203700 | I14: End Jan, 2024
A15: Invoice No. 57-230121 - Dated 31-Oct-2023 | B15: 203700 | D15: =D14+'14.Nov.2024'!$B15-'14.Nov.2024'!$C15 -> 203700 | E15: - | F15: - | H15: 203700 | I15: End Feb, 2024
A16: Transfer on 11-Jan-2024 against Invoice No. 57-230121 | C16: 203700 | D16: =D15+'14.Nov.2024'!$B16-'14.Nov.2024'!$C16 -> 0 | E16: - | F16: - | H16: 203700 | I16: End Mar, 2024
A17: Invoice No. 57-230143 - Dated 30-Nov-2023 | B17: 203700 | D17: =D16+'14.Nov.2024'!$B17-'14.Nov.2024'!$C17 -> 203700 | E17: - | F17: - | H17: 203700 | I17: End Apr, 2024
A18: Transfer on 26-Jan-2024 against Invoice No. 57-230143 | C18: 203700 | D18: =D17+'14.Nov.2024'!$B18-'14.Nov.2024'!$C18 -> 0 | E18: - | F18: - | H18: 203700 | I18: End May, 2024
A19: Invoice No. 57-230159 - Dated 31-Dec-2023 | B19: 203700 | D19: =D18+'14.Nov.2024'!$B19-'14.Nov.2024'!$C19 -> 203700 | E19: - | F19: - | H19: =SUM(H7:H18) -> 2546250 | I19: =B5-H19+J11+K11+L11-M11 -> -2037000
A20: Transfer on 29-Feb-2024 against Invoice No. 57-230159 | C20: 203700 | D20: =D19+'14.Nov.2024'!$B20-'14.Nov.2024'!$C20 -> 0 | E20: - | F20: -
A21: Invoice No. 57-230175 - Dated 31-Jan-2024 | B21: 203700 | D21: =D20+'14.Nov.2024'!$B21-'14.Nov.2024'!$C21 -> 203700 | E21: - | F21: -
A22: Invoice No. 57-230195 - Dated 29-Feb-2024 | B22: 203700 | D22: =D21+'14.Nov.2024'!$B22-'14.Nov.2024'!$C22 -> 407400 | E22: - | F22: -
A23: Invoice No. 57-230202 - Dated 18-Mar-2024 | B23: 20328 | D23: =D22+'14.Nov.2024'!$B23-'14.Nov.2024'!$C23 -> 427728 | E23: - | F23: -
A24: Transfer on 28-Mar-2024 against Invoice No. 57-230175 | C24: 203700 | D24: =D23+'14.Nov.2024'!$B24-'14.Nov.2024'!$C24 -> 224028 | E24: - | F24: -
A25: Transfer on 28-Mar-2024 against Invoice No. 57-230202 (SoundLab - 10% ) | C25: =224028-C24 -> 20328 | D25: =D24+'14.Nov.2024'!$B25-'14.Nov.2024'!$C25 -> 203700 | E25: - | F25: -
A26: Transfer on 28-Apr-2024 against Invoice No. 57-230195 | C26: 203700 | D26: =D25+'14.Nov.2024'!$B26-'14.Nov.2024'!$C26 -> 0 | E26: - | F26: -
A27: Invoice No. 57-230215 - Dated 31-Mar-2024 | B27: 203700 | D27: =D26+'14.Nov.2024'!$B27-'14.Nov.2024'!$C27 -> 203700 | E27: - | F27: -
A28: Transfer on 02-Jul-2024 against Invoice No. 57-230215 | C28: 203700 | D28: =D27+'14.Nov.2024'!$B28-'14.Nov.2024'!$C28 -> 0 | E28: - | F28: -
A29: Invoice No. 57-240013 - Dated 30-Apr-2024 | B29: 203700 | D29: =D28+'14.Nov.2024'!$B29-'14.Nov.2024'!$C29 -> 203700 | E29: Invoice 11: End April 24 as per agreed proposal dated on 21st June 2023 | F29: -
A30: Invoice No. 57-240028 - Dated 31-May-2024 | B30: 498272.25 | D30: =D29+'14.Nov.2024'!$B30-'14.Nov.2024'!$C30 -> 701972.25 | E30: Invoice 12: End May 24 as per agreed proposal dated on 21st June 2023 - SoundLab - 50% on delivery of Phase 1 - VO2 Architectural Support - May 2024 | F30: -
A31: Invoice No. 57-240063 - Dated 30-Jun-2024 | B31: 280628.25 | D31: =D30+'14.Nov.2024'!$B31-'14.Nov.2024'!$C31 -> 982600.5 | E31: VO2 Architectural Support - June 20242 - SoundLab - 40% on delivery of SoundLab presentation - Soundlab - Flight upgrade cost MAD-DXB for Stuart Clarke as instructed by Stuart Magee | F31: -
A32: Invoice No. 57-240085 - Dated 31-Jul-2024 | B32: 487683 | D32: =D31+'14.Nov.2024'!$B32-'14.Nov.2024'!$C32 -> 1470283.5 | E32: VO2 Architectural Support - July 2024 - Invoice 13: End Jul 24 as per agreed proposal dated on 19 June 2024 - IAG review - mobilisation | F32: -
A33: Invoice No. 57-240101 - Dated 31-Aug-2024 | B33: 390907.65 | D33: =D32+'14.Nov.2024'!$B33-'14.Nov.2024'!$C33 -> 1861191.1 | E33: VO3 Invoice 14: End Aug 24 Technical Advisory Services as per agreed proposal dated on 28 June 2024 - VO3 Architectural Support - August 2024 as per agreed proposal dated on 28 June 2024 - VO4 MEP Technical review of IAG project- 1st review as per agreed proposal dated on 19 June 2024 - VO5 Extension of Services – Fernando Garcia First trip on Aug 2024 as per agreed proposal dated on 16 July 2024 | F33: -
A34: Transfer on 22-Oct-2024 against Invoice No. 57-240013, 57-240028, 57-240063, 57-240101 | C34: 976217 | D34: =D33+'14.Nov.2024'!$B34-'14.Nov.2024'!$C34 -> 884974.15 | F34: - | H34: =280628.25+498272.25+203700 -> 982600.5 | I34: =H34-6384 -> 976216.5
A35: Invoice No. 57-240116 - Dated 27-Sep-2024 | B35: 477215.55 | D35: =D34+'14.Nov.2024'!$B35-'14.Nov.2024'!$C35 -> 1362189.7 | E35: Invoice 15: End Sep 24 as per agreed proposal dated on 19 June 2024 , VO3 Architectural Support - September2024 , VO5 Extension of Services – Fernando Garcia September 2024 | F35: -
D36: =D35+'14.Nov.2024'!$B36-'14.Nov.2024'!$C36 -> 1362189.7 | E36: - | F36: -
A37: Total | B37: =SUBTOTAL(9,B5:B36) -> 5006834.7 | C37: =SUBTOTAL(9,C5:C36) -> 3644645 | D37: =B37-C37 -> 1362189.7
A39: % of Amount paid | C39: ='14.Nov.2024'!$C$37/'14.Nov.2024'!$B$37 -> 0.72793396

Sheet 13.Sep.2024
A1: Arup Gulf Limited | I1: 45548
A2: =_xlfn.CONCAT("Statement of Account as of ",TEXT(I1,"MMMMMMM DD, YYYY")) -> Statement of Account as of September 13, 2024
A4: Particulars | B4: Contract Value --AED-- | C4: Payment --AED-- | D4: Balance --AED-- | E4: Balance --AED-- | F4: Remarks | G4: Description | H4: Notes
A5: Contract Value - 20% of AED 2,546,250 | B5: 509250 | D5: =B5-C5 -> 509250 | F5: - | G5: - | H5: -
A6: Transfer on 10-Jul-2023 against 20% Of Contract Value | C6: 509250 | D6: =D5+'13.Sep.2024'!$B6-'13.Sep.2024'!$C6 -> 0 | F6: - | G6: - | H6: -
A7: Contract Value - 20% of AED 2,546,250 | B7: 509250 | D7: =D6+'13.Sep.2024'!$B7-'13.Sep.2024'!$C7 -> 509250 | F7: - | G7: - | H7: -
A8: Transfer on 10-Jul-2023 against 20% Of Contract Value | C8: 509250 | D8: =D7+'13.Sep.2024'!$B8-'13.Sep.2024'!$C8 -> 0 | F8: - | G8: - | H8: -
A9: Invoice No. 57-230079 - Dated 17-Aug-2023 | B9: 135800.7 | D9: =D8+'13.Sep.2024'!$B9-'13.Sep.2024'!$C9 -> 135800.7 | F9: - | G9: - | H9: -
A10: Transfer on 28-Aug-2023 against Invoice No. 57-230079 | C10: 135800.7 | D10: =D9+'13.Sep.2024'!$B10-'13.Sep.2024'!$C10 -> 0 | F10: - | G10: - | H10: -
A11: Invoice No. 57-230090 - Dated 31-Aug-2023 | B11: 135799.65 | D11: =D10+'13.Sep.2024'!$B11-'13.Sep.2024'!$C11 -> 135799.65 | F11: - | G11: - | H11: -
A12: Transfer on 27-Sep-2023 against Invoice No. 57-230090 | C12: 135799.65 | D12: =D11+'13.Sep.2024'!$B12-'13.Sep.2024'!$C12 -> 0 | F12: - | G12: - | H12: -
A13: Invoice No. 57-230106 - Dated 30-Sep-2023 | B13: 135799.65 | D13: =D12+'13.Sep.2024'!$B13-'13.Sep.2024'!$C13 -> 135799.65 | F13: - | G13: - | H13: -
A14: Transfer on 27-Nov-2023 against Invoice No. 57-230106 | C14: 135799.65 | D14: =D13+'13.Sep.2024'!$B14-'13.Sep.2024'!$C14 -> 0 | F14: - | G14: - | H14: -
A15: Invoice No. 57-230121 - Dated 31-Oct-2023 | B15: 203700 | D15: =D14+'13.Sep.2024'!$B15-'13.Sep.2024'!$C15 -> 203700 | F15: - | G15: - | H15: -
A16: Transfer on 11-Jan-2024 against Invoice No. 57-230121 | C16: 203700 | D16: =D15+'13.Sep.2024'!$B16-'13.Sep.2024'!$C16 -> 0 | F16: - | G16: - | H16: -
A17: Invoice No. 57-230143 - Dated 30-Nov-2023 | B17: 203700 | D17: =D16+'13.Sep.2024'!$B17-'13.Sep.2024'!$C17 -> 203700 | F17: - | G17: - | H17: -
A18: Transfer on 26-Jan-2024 against Invoice No. 57-230143 | C18: 203700 | D18: =D17+'13.Sep.2024'!$B18-'13.Sep.2024'!$C18 -> 0 | F18: - | G18: - | H18: -
A19: Invoice No. 57-230159 - Dated 31-Dec-2023 | B19: 203700 | D19: =D18+'13.Sep.2024'!$B19-'13.Sep.2024'!$C19 -> 203700 | F19: - | G19: - | H19: -
A20: Transfer on 29-Feb-2024 against Invoice No. 57-230159 | C20: 203700 | D20: =D19+'13.Sep.2024'!$B20-'13.Sep.2024'!$C20 -> 0 | F20: - | G20: - | H20: -
A21: Invoice No. 57-230175 - Dated 31-Jan-2024 | B21: 203700 | D21: =D20+'13.Sep.2024'!$B21-'13.Sep.2024'!$C21 -> 203700 | F21: - | G21: - | H21: -
A22: Invoice No. 57-230195 - Dated 29-Feb-2024 | B22: 203700 | D22: =D21+'13.Sep.2024'!$B22-'13.Sep.2024'!$C22 -> 407400 | F22: - | G22: - | H22: -
A23: Invoice No. 57-230202 - Dated 18-Mar-2024 | B23: 20328 | D23: =D22+'13.Sep.2024'!$B23-'13.Sep.2024'!$C23 -> 427728 | F23: - | G23: - | H23: -
A24: Transfer on 28-Mar-2024 against Invoice No. 57-230175 | C24: 203700 | D24: =D23+'13.Sep.2024'!$B24-'13.Sep.2024'!$C24 -> 224028 | F24: - | G24: - | H24: -
A25: Transfer on 28-Mar-2024 against Invoice No. 57-230202 (SoundLab - 10% ) | C25: =224028-C24 -> 20328 | D25: =D24+'13.Sep.2024'!$B25-'13.Sep.2024'!$C25 -> 203700 | F25: - | G25: - | H25: -
A26: Transfer on 28-Apr-2024 against Invoice No. 57-230195 | C26: 203700 | D26: =D25+'13.Sep.2024'!$B26-'13.Sep.2024'!$C26 -> 0 | F26: - | G26: - | H26: -
A27: Invoice No. 57-230215 - Dated 31-Mar-2024 | B27: 203700 | D27: =D26+'13.Sep.2024'!$B27-'13.Sep.2024'!$C27 -> 203700 | F27: - | G27: - | H27: -
A28: Transfer on 02-Jul-2024 against Invoice No. 57-230215 | C28: 203700 | D28: =D27+'13.Sep.2024'!$B28-'13.Sep.2024'!$C28 -> 0 | F28: - | G28: - | H28: -
A29: Invoice No. 57-240013 - Dated 30-Apr-2024 | B29: 203700 | D29: =D28+'13.Sep.2024'!$B29-'13.Sep.2024'!$C29 -> 203700 | F29: Invoice 11: End April 24 as per agreed proposal dated on 21st June 2023 | G29: - | H29: - | J29: =Table1[[#This Row],[Balance --AED--]] -> 203700
A30: Invoice No. 57-240028 - Dated 31-May-2024 | B30: 498272.25 | D30: =D29+'13.Sep.2024'!$B30-'13.Sep.2024'!$C30 -> 701972.25 | F30: Invoice 12: End May 24 as per agreed proposal dated on 21st June 2023 - SoundLab - 50% on delivery of Phase 1 - VO2 Architectural Support - May 2024 | G30: - | H30: - | J30: =Table1[[#This Row],[Contract Value --AED--]] -> 498272.25
A31: Invoice No. 57-240063 - Dated 30-Jun-2024 | B31: 280628.25 | D31: =D30+'13.Sep.2024'!$B31-'13.Sep.2024'!$C31 -> 982600.5 | F31: VO2 Architectural Support - June 20242 - SoundLab - 40% on delivery of SoundLab presentation - Soundlab - Flight upgrade cost MAD-DXB for Stuart Clarke as instructed by Stuart Magee | G31: - | H31: - | J31: =Table1[[#This Row],[Contract Value --AED--]]-6384 -> 274244.25
A32: Invoice No. 57-240085 - Dated 31-Jul-2024 | B32: 487683 | D32: =D31+'13.Sep.2024'!$B32-'13.Sep.2024'!$C32 -> 1470283.5 | F32: VO2 Architectural Support - July 2024 - Invoice 13: End Jul 24 as per agreed proposal dated on 19 June 2024 - IAG review - mobilisation | G32: - | H32: -
A33: Invoice No. 57-240101 - Dated 31-Aug-2024 | B33: 390907.65 | D33: =D32+'13.Sep.2024'!$B33-'13.Sep.2024'!$C33 -> 1861191.1 | F33: VO3 Invoice 14: End Aug 24 Technical Advisory Services as per agreed proposal dated on 28 June 2024 - VO3 Architectural Support - August 2024 as per agreed proposal dated on 28 June 2024 - VO4 MEP Technical review of IAG project- 1st review as per agreed proposal dated on 19 June 2024 - VO5 Extension of Services – Fernando Garcia First trip on Aug 2024 as per agreed proposal dated on 16 July 2024 | G33: - | H33: -
D34: =D33+'13.Sep.2024'!$B34-'13.Sep.2024'!$C34 -> 1861191.1 | F34: - | G34: - | H34: -
A35: Total | B35: =SUBTOTAL(9,B5:B34) -> 4529619.2 | C35: =SUBTOTAL(9,C5:C34) -> 2668428 | D35: =B35-C35 -> 1861191.2
A37: % of Amount paid | C37: ='13.Sep.2024'!$C$35/'13.Sep.2024'!$B$35 -> 0.58910648
F39: 509250 | G39: Mobilisation
F40: 135800.7 | G40: End Jul, 2023 | H40: Concept | I40: Scheme | J40: Digital Design | K40: Total
F41: 135799.65 | G41: End Aug, 2023 | H41: =485000 -> 485000 | I41: 970000 | J41: 970000 | K41: =SUM(H41:J41) -> 2425000
F42: 135799.65 | G42: End Sep, 2023 | H42: =H41*5% -> 24250 | I42: =I41*5% -> 48500 | J42: =J41*5% -> 48500 | K42: =K41*5% -> 121250
F43: 203700 | G43: End Oct, 2023 | H43: =H41+H42 -> 509250 | I43: =I41+I42 -> 1018500 | J43: =J41+J42 -> 1018500 | K43: =K41+K42 -> 2546250
...

Sheet 09.Jul.2024
A1: Arup Gulf Limited | G1: 45482
A2: =_xlfn.CONCAT("Statement of Account as of ",TEXT(G1,"MMMMMMM DD, YYYY")) -> Statement of Account as of July 09, 2024
A4: Particulars | B4: Contract Value --AED-- | C4: Payment --AED-- | D4: Balance --AED--
A5: Contract Value | B5: 2546250 | D5: =B5-C5 -> 2546250
A6: Transfer on Jul 10, 2023 against Inv ….. | C6: 509250 | D6: =D5+'09.Jul.2024'!$B6-'09.Jul.2024'!$C6 -> 2037000
A7: Transfer on Aug 28, 2023 against Inv 57-230079 | C7: 135800.75 | D7: =D6+'09.Jul.2024'!$B7-'09.Jul.2024'!$C7 -> 1901199.2
A8: Transfer on Sep 27, 2023 against Inv 57-230090 | C8: 135799.65 | D8: =D7+'09.Jul.2024'!$B8-'09.Jul.2024'!$C8 -> 1765399.6
A9: Transfer on Nov 27, 2023 against Inv 57-230106 | C9: 135799.65 | D9: =D8+'09.Jul.2024'!$B9-'09.Jul.2024'!$C9 -> 1629600
A10: Transfer on Jan 11, 2024 against Inv 57-230121 | C10: 203700 | D10: =D9+'09.Jul.2024'!$B10-'09.Jul.2024'!$C10 -> 1425900
A11: Transfer on Jan 26, 2024 against Inv 57-230143 | C11: 203700 | D11: =D10+'09.Jul.2024'!$B11-'09.Jul.2024'!$C11 -> 1222200
A12: Transfer on Feb 29, 2024 against Inv 57-230159 | C12: 203700 | D12: =D11+'09.Jul.2024'!$B12-'09.Jul.2024'!$C12 -> 1018500
A13: Transfer on Mar 28, 2024 against Inv 57-230175 | C13: 203700 | D13: =D12+'09.Jul.2024'!$B13-'09.Jul.2024'!$C13 -> 814799.95
A14: Transfer on Apr 28, 2024 against Inv 57-230195 | C14: 203700 | D14: =D13+'09.Jul.2024'!$B14-'09.Jul.2024'!$C14 -> 611099.95
A15: Transfer on Jul 02, 2024 against Inv 57-230215 | C15: 203700 | D15: =D14+'09.Jul.2024'!$B15-'09.Jul.2024'!$C15 -> 407399.95
A17: Total | B17: =SUBTOTAL(9,B5:B16) -> 2546250 | C17: =SUBTOTAL(9,C5:C16) -> 2138850 | D17: =B17-C17 -> 407399.95
A19: % of Amount paid | C19: ='09.Jul.2024'!$C$17/'09.Jul.2024'!$B$17 -> 0.84000002
F21: 509250 | G21: Mobilisation
F22: 135800.7 | G22: End Jul, 2023 | H22: Concept | I22: Scheme | J22: Digital Design | K22: Total
F23: 135799.65 | G23: End Aug, 2023 | H23: =485000 -> 485000 | I23: 970000 | J23: 970000 | K23: =SUM(H23:J23) -> 2425000
F24: 135799.65 | G24: End Sep, 2023 | H24: =H23*5% -> 24250 | I24: =I23*5% -> 48500 | J24: =J23*5% -> 48500 | K24: =K23*5% -> 121250
F25: 203700 | G25: End Oct, 2023 | H25: =H23+H24 -> 509250 | I25: =I23+I24 -> 1018500 | J25: =J23+J24 -> 1018500 | K25: =K23+K24 -> 2546250
F26: 203700 | G26: End Nov, 2023
F27: 203700 | G27: End Dec, 2023
F28: 203700 | G28: End Jan, 2024
F29: 203700 | G29: End Feb, 2024
F30: 203700 | G30: End Mar, 2024
F31: 203700 | G31: End Apr, 2024
F32: 203700 | G32: End May, 2024
F33: =SUM(F21:F32) -> 2546250 | G33: =B5-F33+H25+I25+J25-K25 -> 0

Sheet 08.Jul.2024
A1: Arup Gulf Limited | E1: 45481
A2: =_xlfn.CONCAT("Statement of Accounts as of ",TEXT(E1,"MMMMMMM DD, YYYY")) -> Statement of Accounts as of July 08, 2024
A4: Particulars | B4: Contract Value --AED-- | C4: Payment --AED-- | D4: Balance --AED--
A5: Contract Value | B5: 2546250 | D5: =B5-C5 -> 2546250
A6: Transfer on Jul 10, 2023 against Inv ….. | C6: 509250 | D6: =D5+'08.Jul.2024'!$B6-'08.Jul.2024'!$C6 -> 2037000
A7: Transfer on Aug 28, 2023 against Inv 57-230079 | C7: 135800.7 | D7: =D6+'08.Jul.2024'!$B7-'08.Jul.2024'!$C7 -> 1901199.3
A8: Transfer on Sep 27, 2023 against Inv 57-230090 | C8: 135799.65 | D8: =D7+'08.Jul.2024'!$B8-'08.Jul.2024'!$C8 -> 1765399.7
A9: Transfer on Nov 27, 2023 against Inv 57-230106 | C9: 135799.65 | D9: =D8+'08.Jul.2024'!$B9-'08.Jul.2024'!$C9 -> 1629600
A10: Transfer on Jan 11, 2024 against Inv 57-230121 | C10: 203700 | D10: =D9+'08.Jul.2024'!$B10-'08.Jul.2024'!$C10 -> 1425900
A11: Transfer on Jan 26, 2024 against Inv 57-230143 | C11: 203700 | D11: =D10+'08.Jul.2024'!$B11-'08.Jul.2024'!$C11 -> 1222200
A12: Transfer on Feb 29, 2024 against Inv 57-230159 | C12: 203700 | D12: =D11+'08.Jul.2024'!$B12-'08.Jul.2024'!$C12 -> 1018500
A17: Total | B17: =SUBTOTAL(9,B5:B16) -> 2546250 | C17: =SUBTOTAL(9,C5:C16) -> 1527750 | D17: =B17-C17 -> 1018500
A19: % of Amount paid | C19: ='08.Jul.2024'!$C$17/'08.Jul.2024'!$B$17 -> 0.6
F21: 509250 | G21: Mobilisation
F22: 135800.7 | G22: End Jul, 2023 | H22: Concept | I22: Scheme | J22: Digital Design | K22: Total
F23: 135799.65 | G23: End Aug, 2023 | H23: =485000 -> 485000 | I23: 970000 | J23: 970000 | K23: =SUM(H23:J23) -> 2425000
F24: 135799.65 | G24: End Sep, 2023 | H24: =H23*5% -> 24250 | I24: =I23*5% -> 48500 | J24: =J23*5% -> 48500 | K24: =K23*5% -> 121250
F25: 203700 | G25: End Oct, 2023 | H25: =H23+H24 -> 509250 | I25: =I23+I24 -> 1018500 | J25: =J23+J24 -> 1018500 | K25: =K23+K24 -> 2546250
F26: 203700 | G26: End Nov, 2023
F27: 203700 | G27: End Dec, 2023
F28: 203700 | G28: End Jan, 2024
F29: 203700 | G29: End Feb, 2024
F30: 203700 | G30: End Mar, 2024
F31: 203700 | G31: End Apr, 2024
F32: 203700 | G32: End May, 2024
F33: =SUM(F21:F32) -> 2546250 | G33: =B5-F33+H25+I25+J25-K25 -> 0

Sheet 31.Dec.2023
A1: Arup Gulf Limited
A2: Statement of Accounts as of Dec 31, 2023
A4: Particulars | B4: Contract Value --AED-- | C4: Payment --AED-- | D4: Balance --AED--
A5: Contract Value | B5: 2546250 | D5: =B5-C5 -> 2546250
A6: Transfer on Jul 10, 2023 against Inv ….. | C6: 509250 | D6: =B6-C6 -> -509250
A7: Transfer on Aug 28, 2023 against Inv 57-230079 | C7: 135800.7 | D7: =D6+B7-C7 -> -645050.7
A8: Transfer on Sep 27, 2023 against Inv 57-230090 | C8: 135799.65 | D8: =D7+B8-C8 -> -780850.35
A9: Transfer on Nov 27, 2023 against Inv 57-230106 | C9: 135799.65 | D9: =D8+B9-C9 -> -916650
A10: Total | B10: =SUBTOTAL(109,Table13458151617[Contract Value --AED--]) -> 2546250 | C10: =SUBTOTAL(109,Table13458151617[Payment --AED--]) -> 916650 | D10: =Table13458151617[[#Totals],[Contract Value --AED--]]-Table13458151617[[#Totals],[Payment --AED--]] -> 1629600
A12: % of Amount paid | C12: =Table13458151617[[#Totals],[Payment --AED--]]/Table13458151617[[#Totals],[Contract Value --AED--]] -> 0.36

Sheet Vendor List
A2: Vendor Name | B2: CURRENCY | C2: % PAID | D2: CONTRACT VALUE | E2: PAYMENT | F2: BALANCE
A3: Al Hai & Al Mukaddam for Geotechnical works LLC | B3: AED | C3: =#REF! -> #REF! | D3: =#REF! -> #REF! | E3: =#REF! -> #REF! | F3: =#REF! -> #REF!
A4: Al Tamimi & Company Ltd
A5: Anta Travel & Tours
A6: Arup Gulf Limited | B6: AED | C6: ='08.Jul.2024'!C19 -> 0.6 | D6: ='08.Jul.2024'!$B$17 -> 2546250 | E6: ='08.Jul.2024'!$C$17 -> 1527750 | F6: ='08.Jul.2024'!$D$17 -> 1018500
A7: Atelier One
A8: BETC BNP | B8: EUR | C8: =#REF! -> #REF! | D8: =#REF! -> #REF! | E8: =#REF! -> #REF! | F8: =#REF! -> #REF!
A9: CBRE Dubai LLC | B9: AED | C9: =#REF! -> #REF! | D9: =#REF! -> #REF! | E9: =#REF! -> #REF! | F9: =#REF! -> #REF!
A10: Dezire Project Consultant
A11: FALCON SURVEY ENGINEERING Consultants
A12: Flint Culture MENA Marketing Management LLC
A13: Korn/Ferry (Schweiz) GmbH
A14: LuckyLion FZC-LLC | B14: AED | C14: =#REF! -> #REF! | D14: =#REF! -> #REF! | E14: =#REF! -> #REF! | F14: =#REF! -> #REF!
A15: Quali Consult Engineers | B15: AED | C15: =#REF! -> #REF! | D15: =#REF! -> #REF! | E15: =#REF! -> #REF! | F15: =#REF! -> #REF!
A16: March Made LLC | B16: USD | C16: =#REF! -> #REF! | D16: =#REF! -> #REF! | E16: =#REF! -> #REF! | F16: =#REF! -> #REF!
A17: Mazarine Middle East FZ-LLC | B17: AED | C17: =#REF! -> #REF! | D17: =#REF! -> #REF! | E17: =#REF! -> #REF! | F17: =#REF! -> #REF!
A18: Pentagram Design Limited | B18: GBP | C18: =#REF! -> #REF! | D18: =#REF! -> #REF! | E18: =#REF! -> #REF! | F18: =#REF! -> #REF!
A19: RCR Aranda Pigem Vilalta Arquitectes SLP | B19: AED | C19: =#REF! -> #REF! | D19: =#REF! -> #REF! | E19: =#REF! -> #REF! | F19: =#REF! -> #REF!
A20: Surface DMCC | B20: AED | C20: =#REF! -> #REF! | D20: =#REF! -> #REF! | E20: =#REF! -> #REF! | F20: =#REF! -> #REF!
A21: WSP Middle East Limited - Dubai Branch | B21: AED | C21: =#REF! -> #REF! | D21: =#REF! -> #REF! | E21: =#REF! -> #REF! | F21: =#REF! -> #REF!
